2018-06-07 14:30:09,490 ERROR: Exception on / [GET] [in c:\users\woongw~1\envs\flaskt~1\lib\site-packages\flask\app.py:1560]
Traceback (most recent call last):
  File "c:\users\woongw~1\envs\flaskt~1\lib\site-packages\flask\app.py", line 1982, in wsgi_app
    response = self.full_dispatch_request()
  File "c:\users\woongw~1\envs\flaskt~1\lib\site-packages\flask\app.py", line 1614, in full_dispatch_request
    rv = self.handle_user_exception(e)
  File "c:\users\woongw~1\envs\flaskt~1\lib\site-packages\flask\app.py", line 1517, in handle_user_exception
    reraise(exc_type, exc_value, tb)
  File "c:\users\woongw~1\envs\flaskt~1\lib\site-packages\flask\app.py", line 1612, in full_dispatch_request
    rv = self.dispatch_request()
  File "c:\users\woongw~1\envs\flaskt~1\lib\site-packages\flask\app.py", line 1598, in dispatch_request
    return self.view_functions[rule.endpoint](**req.view_args)
  File "c:\users\woongw~1\envs\flaskt~1\lib\site-packages\flask_login\utils.py", line 228, in decorated_view
    return func(*args, **kwargs)
  File "C:\Users\Woong Wen Tat\flask-microblog\app\main\routes.py", line 47, in index
    prev_url=prev_url)
  File "c:\users\woongw~1\envs\flaskt~1\lib\site-packages\flask\templating.py", line 134, in render_template
    context, ctx.app)
  File "c:\users\woongw~1\envs\flaskt~1\lib\site-packages\flask\templating.py", line 116, in _render
    rv = template.render(context)
  File "c:\users\woongw~1\envs\flaskt~1\lib\site-packages\jinja2\environment.py", line 1008, in render
    return self.environment.handle_exception(exc_info, True)
  File "c:\users\woongw~1\envs\flaskt~1\lib\site-packages\jinja2\environment.py", line 780, in handle_exception
    reraise(exc_type, exc_value, tb)
  File "C:\Users\Woong Wen Tat\flask-microblog\app\templates\index.html", line 2, in top-level template code
    {% import 'bootstrap/wtf.html' as wtf %}
  File "C:\Users\Woong Wen Tat\flask-microblog\app\templates\base.html", line 1, in top-level template code
    {% extends 'bootstrap/base.html' %}
  File "c:\users\woongw~1\envs\flaskt~1\lib\site-packages\flask_bootstrap\templates\bootstrap\base.html", line 1, in top-level template code
    {% block doc -%}
  File "c:\users\woongw~1\envs\flaskt~1\lib\site-packages\flask_bootstrap\templates\bootstrap\base.html", line 4, in block "doc"
    {%- block html %}
  File "c:\users\woongw~1\envs\flaskt~1\lib\site-packages\flask_bootstrap\templates\bootstrap\base.html", line 20, in block "html"
    {% block body -%}
  File "c:\users\woongw~1\envs\flaskt~1\lib\site-packages\flask_bootstrap\templates\bootstrap\base.html", line 23, in block "body"
    {% block content -%}
  File "C:\Users\Woong Wen Tat\flask-microblog\app\templates\base.html", line 60, in block "content"
    {% if current_user.is_authenticated %}
  File "C:\Users\Woong Wen Tat\flask-microblog\app\models.py", line 106, in get_tasks_in_progress
    return Task.query.filter_by(user=self, complete=False).all()
  File "c:\users\woongw~1\envs\flaskt~1\lib\site-packages\sqlalchemy\orm\query.py", line 2703, in all
    return list(self)
  File "c:\users\woongw~1\envs\flaskt~1\lib\site-packages\sqlalchemy\orm\query.py", line 2855, in __iter__
    return self._execute_and_instances(context)
  File "c:\users\woongw~1\envs\flaskt~1\lib\site-packages\sqlalchemy\orm\query.py", line 2878, in _execute_and_instances
    result = conn.execute(querycontext.statement, self._params)
  File "c:\users\woongw~1\envs\flaskt~1\lib\site-packages\sqlalchemy\engine\base.py", line 945, in execute
    return meth(self, multiparams, params)
  File "c:\users\woongw~1\envs\flaskt~1\lib\site-packages\sqlalchemy\sql\elements.py", line 263, in _execute_on_connection
    return connection._execute_clauseelement(self, multiparams, params)
  File "c:\users\woongw~1\envs\flaskt~1\lib\site-packages\sqlalchemy\engine\base.py", line 1053, in _execute_clauseelement
    compiled_sql, distilled_params
  File "c:\users\woongw~1\envs\flaskt~1\lib\site-packages\sqlalchemy\engine\base.py", line 1189, in _execute_context
    context)
  File "c:\users\woongw~1\envs\flaskt~1\lib\site-packages\sqlalchemy\engine\base.py", line 1402, in _handle_dbapi_exception
    exc_info
  File "c:\users\woongw~1\envs\flaskt~1\lib\site-packages\sqlalchemy\util\compat.py", line 203, in raise_from_cause
    reraise(type(exception), exception, tb=exc_tb, cause=cause)
  File "c:\users\woongw~1\envs\flaskt~1\lib\site-packages\sqlalchemy\engine\base.py", line 1182, in _execute_context
    context)
  File "c:\users\woongw~1\envs\flaskt~1\lib\site-packages\sqlalchemy\engine\default.py", line 470, in do_execute
    cursor.execute(statement, parameters)
OperationalError: (sqlite3.OperationalError) no such table: task [SQL: u'SELECT task.id AS task_id, task.name AS task_name, task.description AS task_description, task.user_id AS task_user_id, task.complete AS task_complete \nFROM task \nWHERE ? = task.user_id AND task.complete = 0'] [parameters: (1,)]
2018-06-07 14:31:22,687 INFO: Microblog startup [in C:\Users\Woong Wen Tat\flask-microblog\app\__init__.py:81]
2018-06-07 14:31:31,904 INFO: Microblog startup [in C:\Users\Woong Wen Tat\flask-microblog\app\__init__.py:81]
2018-06-07 14:31:38,953 INFO: Microblog startup [in C:\Users\Woong Wen Tat\flask-microblog\app\__init__.py:81]
2018-06-07 14:55:13,329 INFO: Microblog startup [in C:\Users\Woong Wen Tat\flask-microblog\app\__init__.py:84]
2018-06-07 14:55:17,252 ERROR: Exception on /api/users/1 [GET] [in c:\users\woongw~1\envs\flaskt~1\lib\site-packages\flask\app.py:1560]
Traceback (most recent call last):
  File "c:\users\woongw~1\envs\flaskt~1\lib\site-packages\flask\app.py", line 1982, in wsgi_app
    response = self.full_dispatch_request()
  File "c:\users\woongw~1\envs\flaskt~1\lib\site-packages\flask\app.py", line 1614, in full_dispatch_request
    rv = self.handle_user_exception(e)
  File "c:\users\woongw~1\envs\flaskt~1\lib\site-packages\flask\app.py", line 1517, in handle_user_exception
    reraise(exc_type, exc_value, tb)
  File "c:\users\woongw~1\envs\flaskt~1\lib\site-packages\flask\app.py", line 1612, in full_dispatch_request
    rv = self.dispatch_request()
  File "c:\users\woongw~1\envs\flaskt~1\lib\site-packages\flask\app.py", line 1598, in dispatch_request
    return self.view_functions[rule.endpoint](**req.view_args)
  File "C:\Users\Woong Wen Tat\flask-microblog\app\api\users.py", line 7, in get_user
    return jsonify(User.query.get_or_404(id).to_dict())
NameError: global name 'User' is not defined
2018-06-07 15:04:22,102 INFO: Microblog startup [in C:\Users\Woong Wen Tat\flask-microblog\app\__init__.py:84]
2018-06-07 15:08:47,927 INFO: Microblog startup [in C:\Users\Woong Wen Tat\flask-microblog\app\__init__.py:84]
2018-06-07 15:08:51,665 ERROR: Exception on /api/users [GET] [in c:\users\woongw~1\envs\flaskt~1\lib\site-packages\flask\app.py:1560]
Traceback (most recent call last):
  File "c:\users\woongw~1\envs\flaskt~1\lib\site-packages\flask\app.py", line 1982, in wsgi_app
    response = self.full_dispatch_request()
  File "c:\users\woongw~1\envs\flaskt~1\lib\site-packages\flask\app.py", line 1614, in full_dispatch_request
    rv = self.handle_user_exception(e)
  File "c:\users\woongw~1\envs\flaskt~1\lib\site-packages\flask\app.py", line 1517, in handle_user_exception
    reraise(exc_type, exc_value, tb)
  File "c:\users\woongw~1\envs\flaskt~1\lib\site-packages\flask\app.py", line 1612, in full_dispatch_request
    rv = self.dispatch_request()
  File "c:\users\woongw~1\envs\flaskt~1\lib\site-packages\flask\app.py", line 1598, in dispatch_request
    return self.view_functions[rule.endpoint](**req.view_args)
  File "C:\Users\Woong Wen Tat\flask-microblog\app\api\users.py", line 13, in get_users
    page = request.args.get('page', 1, type=int)
NameError: global name 'request' is not defined
2018-06-07 15:09:21,081 ERROR: Exception on /api/users [GET] [in c:\users\woongw~1\envs\flaskt~1\lib\site-packages\flask\app.py:1560]
Traceback (most recent call last):
  File "c:\users\woongw~1\envs\flaskt~1\lib\site-packages\flask\app.py", line 1982, in wsgi_app
    response = self.full_dispatch_request()
  File "c:\users\woongw~1\envs\flaskt~1\lib\site-packages\flask\app.py", line 1614, in full_dispatch_request
    rv = self.handle_user_exception(e)
  File "c:\users\woongw~1\envs\flaskt~1\lib\site-packages\flask\app.py", line 1517, in handle_user_exception
    reraise(exc_type, exc_value, tb)
  File "c:\users\woongw~1\envs\flaskt~1\lib\site-packages\flask\app.py", line 1612, in full_dispatch_request
    rv = self.dispatch_request()
  File "c:\users\woongw~1\envs\flaskt~1\lib\site-packages\flask\app.py", line 1598, in dispatch_request
    return self.view_functions[rule.endpoint](**req.view_args)
  File "C:\Users\Woong Wen Tat\flask-microblog\app\api\users.py", line 13, in get_users
    page = request.args.get('page', 1, type=int)
NameError: global name 'request' is not defined
2018-06-07 15:09:46,259 ERROR: Exception on /api/users [GET] [in c:\users\woongw~1\envs\flaskt~1\lib\site-packages\flask\app.py:1560]
Traceback (most recent call last):
  File "c:\users\woongw~1\envs\flaskt~1\lib\site-packages\flask\app.py", line 1982, in wsgi_app
    response = self.full_dispatch_request()
  File "c:\users\woongw~1\envs\flaskt~1\lib\site-packages\flask\app.py", line 1614, in full_dispatch_request
    rv = self.handle_user_exception(e)
  File "c:\users\woongw~1\envs\flaskt~1\lib\site-packages\flask\app.py", line 1517, in handle_user_exception
    reraise(exc_type, exc_value, tb)
  File "c:\users\woongw~1\envs\flaskt~1\lib\site-packages\flask\app.py", line 1612, in full_dispatch_request
    rv = self.dispatch_request()
  File "c:\users\woongw~1\envs\flaskt~1\lib\site-packages\flask\app.py", line 1598, in dispatch_request
    return self.view_functions[rule.endpoint](**req.view_args)
  File "C:\Users\Woong Wen Tat\flask-microblog\app\api\users.py", line 13, in get_users
    page = request.args.get('page', 1, type=int)
NameError: global name 'request' is not defined
