2018-05-27 12:23:55,061 INFO: Microblog startup [in C:\Users\Lumo\Desktop\microblog\app\__init__.py:42]
2018-05-27 12:24:17,025 INFO: Microblog startup [in C:\Users\Lumo\Desktop\microblog\app\__init__.py:42]
2018-05-29 10:30:00,725 INFO: Microblog startup [in C:\Users\Lumo\Desktop\microblog\app\__init__.py:42]
2018-05-29 10:30:35,721 INFO: Microblog startup [in C:\Users\Lumo\Desktop\microblog\app\__init__.py:42]
2018-05-29 10:30:49,069 INFO: Microblog startup [in C:\Users\Lumo\Desktop\microblog\app\__init__.py:42]
2018-05-29 10:32:28,857 INFO: Microblog startup [in C:\Users\Lumo\Desktop\microblog\app\__init__.py:42]
2018-05-29 10:32:38,521 ERROR: Exception on / [GET] [in c:\users\lumo\envs\flask\lib\site-packages\flask\app.py:1761]
Traceback (most recent call last):
  File "c:\users\lumo\envs\flask\lib\site-packages\flask\app.py", line 2292, in wsgi_app
    response = self.full_dispatch_request()
  File "c:\users\lumo\envs\flask\lib\site-packages\flask\app.py", line 1815, in full_dispatch_request
    rv = self.handle_user_exception(e)
  File "c:\users\lumo\envs\flask\lib\site-packages\flask\app.py", line 1718, in handle_user_exception
    reraise(exc_type, exc_value, tb)
  File "c:\users\lumo\envs\flask\lib\site-packages\flask\_compat.py", line 35, in reraise
    raise value
  File "c:\users\lumo\envs\flask\lib\site-packages\flask\app.py", line 1813, in full_dispatch_request
    rv = self.dispatch_request()
  File "c:\users\lumo\envs\flask\lib\site-packages\flask\app.py", line 1799, in dispatch_request
    return self.view_functions[rule.endpoint](**req.view_args)
  File "c:\users\lumo\envs\flask\lib\site-packages\flask_login\utils.py", line 261, in decorated_view
    return func(*args, **kwargs)
  File "C:\Users\Lumo\Desktop\microblog\app\routes.py", line 32, in index
    posts = current_user.follower_posts().all()
  File "c:\users\lumo\envs\flask\lib\site-packages\werkzeug\local.py", line 347, in __getattr__
    return getattr(self._get_current_object(), name)
AttributeError: 'User' object has no attribute 'follower_posts'
2018-05-29 10:32:40,852 ERROR: Exception on /index [GET] [in c:\users\lumo\envs\flask\lib\site-packages\flask\app.py:1761]
Traceback (most recent call last):
  File "c:\users\lumo\envs\flask\lib\site-packages\flask\app.py", line 2292, in wsgi_app
    response = self.full_dispatch_request()
  File "c:\users\lumo\envs\flask\lib\site-packages\flask\app.py", line 1815, in full_dispatch_request
    rv = self.handle_user_exception(e)
  File "c:\users\lumo\envs\flask\lib\site-packages\flask\app.py", line 1718, in handle_user_exception
    reraise(exc_type, exc_value, tb)
  File "c:\users\lumo\envs\flask\lib\site-packages\flask\_compat.py", line 35, in reraise
    raise value
  File "c:\users\lumo\envs\flask\lib\site-packages\flask\app.py", line 1813, in full_dispatch_request
    rv = self.dispatch_request()
  File "c:\users\lumo\envs\flask\lib\site-packages\flask\app.py", line 1799, in dispatch_request
    return self.view_functions[rule.endpoint](**req.view_args)
  File "c:\users\lumo\envs\flask\lib\site-packages\flask_login\utils.py", line 261, in decorated_view
    return func(*args, **kwargs)
  File "C:\Users\Lumo\Desktop\microblog\app\routes.py", line 32, in index
    posts = current_user.follower_posts().all()
  File "c:\users\lumo\envs\flask\lib\site-packages\werkzeug\local.py", line 347, in __getattr__
    return getattr(self._get_current_object(), name)
AttributeError: 'User' object has no attribute 'follower_posts'
2018-05-29 10:32:43,266 ERROR: Exception on /index [GET] [in c:\users\lumo\envs\flask\lib\site-packages\flask\app.py:1761]
Traceback (most recent call last):
  File "c:\users\lumo\envs\flask\lib\site-packages\flask\app.py", line 2292, in wsgi_app
    response = self.full_dispatch_request()
  File "c:\users\lumo\envs\flask\lib\site-packages\flask\app.py", line 1815, in full_dispatch_request
    rv = self.handle_user_exception(e)
  File "c:\users\lumo\envs\flask\lib\site-packages\flask\app.py", line 1718, in handle_user_exception
    reraise(exc_type, exc_value, tb)
  File "c:\users\lumo\envs\flask\lib\site-packages\flask\_compat.py", line 35, in reraise
    raise value
  File "c:\users\lumo\envs\flask\lib\site-packages\flask\app.py", line 1813, in full_dispatch_request
    rv = self.dispatch_request()
  File "c:\users\lumo\envs\flask\lib\site-packages\flask\app.py", line 1799, in dispatch_request
    return self.view_functions[rule.endpoint](**req.view_args)
  File "c:\users\lumo\envs\flask\lib\site-packages\flask_login\utils.py", line 261, in decorated_view
    return func(*args, **kwargs)
  File "C:\Users\Lumo\Desktop\microblog\app\routes.py", line 32, in index
    posts = current_user.follower_posts().all()
  File "c:\users\lumo\envs\flask\lib\site-packages\werkzeug\local.py", line 347, in __getattr__
    return getattr(self._get_current_object(), name)
AttributeError: 'User' object has no attribute 'follower_posts'
2018-05-29 10:34:15,882 INFO: Microblog startup [in C:\Users\Lumo\Desktop\microblog\app\__init__.py:42]
2018-05-29 10:34:22,026 ERROR: Exception on / [GET] [in c:\users\lumo\envs\flask\lib\site-packages\flask\app.py:1761]
Traceback (most recent call last):
  File "c:\users\lumo\envs\flask\lib\site-packages\flask\app.py", line 2292, in wsgi_app
    response = self.full_dispatch_request()
  File "c:\users\lumo\envs\flask\lib\site-packages\flask\app.py", line 1815, in full_dispatch_request
    rv = self.handle_user_exception(e)
  File "c:\users\lumo\envs\flask\lib\site-packages\flask\app.py", line 1718, in handle_user_exception
    reraise(exc_type, exc_value, tb)
  File "c:\users\lumo\envs\flask\lib\site-packages\flask\_compat.py", line 35, in reraise
    raise value
  File "c:\users\lumo\envs\flask\lib\site-packages\flask\app.py", line 1813, in full_dispatch_request
    rv = self.dispatch_request()
  File "c:\users\lumo\envs\flask\lib\site-packages\flask\app.py", line 1799, in dispatch_request
    return self.view_functions[rule.endpoint](**req.view_args)
  File "c:\users\lumo\envs\flask\lib\site-packages\flask_login\utils.py", line 261, in decorated_view
    return func(*args, **kwargs)
  File "C:\Users\Lumo\Desktop\microblog\app\routes.py", line 32, in index
    posts = current_user.followed_posts().all()
  File "c:\users\lumo\envs\flask\lib\site-packages\werkzeug\local.py", line 347, in __getattr__
    return getattr(self._get_current_object(), name)
AttributeError: 'User' object has no attribute 'followed_posts'
2018-05-29 10:34:23,833 ERROR: Exception on /index [GET] [in c:\users\lumo\envs\flask\lib\site-packages\flask\app.py:1761]
Traceback (most recent call last):
  File "c:\users\lumo\envs\flask\lib\site-packages\flask\app.py", line 2292, in wsgi_app
    response = self.full_dispatch_request()
  File "c:\users\lumo\envs\flask\lib\site-packages\flask\app.py", line 1815, in full_dispatch_request
    rv = self.handle_user_exception(e)
  File "c:\users\lumo\envs\flask\lib\site-packages\flask\app.py", line 1718, in handle_user_exception
    reraise(exc_type, exc_value, tb)
  File "c:\users\lumo\envs\flask\lib\site-packages\flask\_compat.py", line 35, in reraise
    raise value
  File "c:\users\lumo\envs\flask\lib\site-packages\flask\app.py", line 1813, in full_dispatch_request
    rv = self.dispatch_request()
  File "c:\users\lumo\envs\flask\lib\site-packages\flask\app.py", line 1799, in dispatch_request
    return self.view_functions[rule.endpoint](**req.view_args)
  File "c:\users\lumo\envs\flask\lib\site-packages\flask_login\utils.py", line 261, in decorated_view
    return func(*args, **kwargs)
  File "C:\Users\Lumo\Desktop\microblog\app\routes.py", line 32, in index
    posts = current_user.followed_posts().all()
  File "c:\users\lumo\envs\flask\lib\site-packages\werkzeug\local.py", line 347, in __getattr__
    return getattr(self._get_current_object(), name)
AttributeError: 'User' object has no attribute 'followed_posts'
2018-05-29 10:35:04,003 INFO: Microblog startup [in C:\Users\Lumo\Desktop\microblog\app\__init__.py:42]
2018-05-29 10:35:10,487 ERROR: Exception on /explore [GET] [in c:\users\lumo\envs\flask\lib\site-packages\flask\app.py:1761]
Traceback (most recent call last):
  File "c:\users\lumo\envs\flask\lib\site-packages\flask\app.py", line 2292, in wsgi_app
    response = self.full_dispatch_request()
  File "c:\users\lumo\envs\flask\lib\site-packages\flask\app.py", line 1815, in full_dispatch_request
    rv = self.handle_user_exception(e)
  File "c:\users\lumo\envs\flask\lib\site-packages\flask\app.py", line 1718, in handle_user_exception
    reraise(exc_type, exc_value, tb)
  File "c:\users\lumo\envs\flask\lib\site-packages\flask\_compat.py", line 35, in reraise
    raise value
  File "c:\users\lumo\envs\flask\lib\site-packages\flask\app.py", line 1813, in full_dispatch_request
    rv = self.dispatch_request()
  File "c:\users\lumo\envs\flask\lib\site-packages\flask\app.py", line 1799, in dispatch_request
    return self.view_functions[rule.endpoint](**req.view_args)
  File "c:\users\lumo\envs\flask\lib\site-packages\flask_login\utils.py", line 261, in decorated_view
    return func(*args, **kwargs)
  File "C:\Users\Lumo\Desktop\microblog\app\routes.py", line 135, in explore
    posts = post.query.order_by(Post.timestamp.desc()).all()
NameError: name 'post' is not defined
2018-05-29 10:36:07,490 INFO: Microblog startup [in C:\Users\Lumo\Desktop\microblog\app\__init__.py:42]
2018-05-29 11:36:39,783 INFO: Microblog startup [in C:\Users\Lumo\Desktop\microblog\app\__init__.py:43]
2018-05-29 11:36:46,001 INFO: Microblog startup [in C:\Users\Lumo\Desktop\microblog\app\__init__.py:43]
2018-05-29 11:37:20,680 INFO: Microblog startup [in C:\Users\Lumo\Desktop\microblog\app\__init__.py:45]
2018-05-29 11:37:58,716 INFO: Microblog startup [in C:\Users\Lumo\Desktop\microblog\app\__init__.py:45]
2018-05-29 16:51:22,864 INFO: Microblog startup [in C:\Users\Lumo\Desktop\microblog\app\__init__.py:47]
2018-05-29 16:51:37,156 INFO: Microblog startup [in C:\Users\Lumo\Desktop\microblog\app\__init__.py:47]
